<?xml version='1.0' encoding='utf-8'?>
<robot name="assembly">
    <link name="MESA-v1">
        <inertial>
            <origin xyz="1.0018864640016567 0.5282232404482216 0.6944188425036134" rpy="0.0 0.0 0.0" />
            <mass value="36.43073826823852" />
            <inertia ixx="11.029207471017287" iyy="21.326666833664646" izz="23.719601290970722" ixy="-0.0804834630601137" iyz="-0.3427373572418621" ixz="-0.0017581700310249748" />
        </inertial>
        <visual name="MESA-v1_visual">
            <origin xyz="0.0 0.0 0.0" rpy="0.0 0.0 0.0" />
            <geometry>
                <mesh filename="meshes/MESA-v1.stl" scale="0.001 0.001 0.001" />
            </geometry>
        </visual>
        <collision name="MESA-v1_collision">
            <origin xyz="0.0 0.0 0.0" rpy="0.0 0.0 0.0" />
            <geometry>
                <mesh filename="meshes/MESA-v1.stl" scale="0.001 0.001 0.001" />
            </geometry>
        </collision>
    </link>
    <link name="CARRO-v1">
        <inertial>
            <origin xyz="0.5009402849217075 -1.566785671859837 -0.49075371056894285" rpy="3.7818280418450374e-124 -0.0 0.0" />
            <mass value="3.9447465504835546" />
            <inertia ixx="0.7667893479068137" iyy="1.4640634143680007" izz="0.7387697850970554" ixy="0.08453766228674199" iyz="0.007058914661190719" ixz="-0.05026208461364835" />
        </inertial>
        <visual name="CARRO-v1_visual">
            <origin xyz="-0.927000000000003 -0.3704192787594452 0.02699999999999747" rpy="-1.5707963267948966 1.859793639850122e-15 -1.5707963267948934" />
            <geometry>
                <mesh filename="meshes/CARRO-v1.stl" scale="0.001 0.001 0.001" />
            </geometry>
        </visual>
        <collision name="CARRO-v1_collision">
            <origin xyz="-0.927000000000003 -0.3704192787594452 0.02699999999999747" rpy="-1.5707963267948966 1.859793639850122e-15 -1.5707963267948934" />
            <geometry>
                <mesh filename="meshes/CARRO-v1.stl" scale="0.001 0.001 0.001" />
            </geometry>
        </collision>
    </link>
    <link name="CASTELO-v1">
        <inertial>
            <origin xyz="-0.1342024466674303 0.4705751678185375 0.04008433719987124" rpy="0.0 -0.0 0.0" />
            <mass value="0.8715628990974349" />
            <inertia ixx="0.001118305461238478" iyy="0.046728246501303694" izz="0.047032112986330255" ixy="2.170103162526072e-06" iyz="-7.343797603186868e-08" ixz="9.413438075833724e-05" />
        </inertial>
        <visual name="CASTELO-v1_visual">
            <origin xyz="-1.964485809999981 -0.0712868616468765 1.1986182812405917" rpy="-1.894780796486719e-14 1.5707963267948806 0" />
            <geometry>
                <mesh filename="meshes/CASTELO-v1.stl" scale="0.001 0.001 0.001" />
            </geometry>
        </visual>
        <collision name="CASTELO-v1_collision">
            <origin xyz="-1.964485809999981 -0.0712868616468765 1.1986182812405917" rpy="-1.894780796486719e-14 1.5707963267948806 0" />
            <geometry>
                <mesh filename="meshes/CASTELO-v1.stl" scale="0.001 0.001 0.001" />
            </geometry>
        </collision>
    </link>
    <link name="Z-v1">
        <inertial>
            <origin xyz="4.644314728352584e-09 -0.007767242090791342 0.2800704494709902" rpy="0.0 -0.0 0.0" />
            <mass value="0.37691577566505097" />
            <inertia ixx="0.02038400084707348" iyy="0.02035537147718891" izz="0.00016610130669569845" ixy="1.099120794378905e-13" iyz="-0.00032772476375519943" ixz="-7.921274747246798e-12" />
        </inertial>
        <visual name="Z-v1_visual">
            <origin xyz="0.541854572902172 -1.1158682808937939 -1.3985906582163483" rpy="-1.0719375054290022e-14 1.3815302178608003e-14 1.5707963267948986" />
            <geometry>
                <mesh filename="meshes/Z-v1.stl" scale="0.001 0.001 0.001" />
            </geometry>
        </visual>
        <collision name="Z-v1_collision">
            <origin xyz="0.541854572902172 -1.1158682808937939 -1.3985906582163483" rpy="-1.0719375054290022e-14 1.3815302178608003e-14 1.5707963267948986" />
            <geometry>
                <mesh filename="meshes/Z-v1.stl" scale="0.001 0.001 0.001" />
            </geometry>
        </collision>
    </link>
    <link name="Tocha_Bocal">
        <inertial>
            <origin xyz="-0.8557192385878881 1.1952881977604812e-16 0.05246760285204614" rpy="0.0 0.0 0.0" />
            <mass value="0.3630181220343261" />
            <inertia ixx="0.00029532837053380945" iyy="0.00029532837053392047" izz="2.707847149574505e-05" ixy="5.551115123125697e-17" iyz="5.212131926284596e-18" ixz="5.547166246391813e-17" />
        </inertial>
        <visual name="Tocha_Bocal_visual">
            <origin xyz="0.0 0.0 0.0" rpy="0.0 0.0 0.0" />
            <geometry>
                <mesh filename="meshes/Tocha_Bocal.stl" scale="0.001 0.001 0.001" />
            </geometry>
        </visual>
        <collision name="Tocha_Bocal_collision">
            <origin xyz="0.0 0.0 0.0" rpy="0.0 0.0 0.0" />
            <geometry>
                <mesh filename="meshes/Tocha_Bocal.stl" scale="0.001 0.001 0.001" />
            </geometry>
        </collision>
    </link>
    <link name="Tocha_Corpo">
        <inertial>
            <origin xyz="4.5726106634447205e-09 -1.4890360944264103e-10 0.09999999566559041" rpy="0.0 -0.0 0.0" />
            <mass value="0.4932300466135968" />
            <inertia ixx="0.0016564309065443261" iyy="0.001656430906543882" izz="2.4661502330491913e-05" ixy="-3.28885513741507e-34" iyz="1.6532666788829158e-47" ixz="-1.6653345369377348e-16" />
        </inertial>
        <visual name="Tocha_Corpo_visual">
            <origin xyz="0.8557192431605004 -1.4890588317939546e-10 -0.1000000043344096" rpy="-1.943013564953089e-14 -8.597654057672277e-17 1.995298892452953e-15" />
            <geometry>
                <mesh filename="meshes/Tocha_Corpo.stl" scale="0.001 0.001 0.001" />
            </geometry>
        </visual>
        <collision name="Tocha_Corpo_collision">
            <origin xyz="0.8557192431605004 -1.4890588317939546e-10 -0.1000000043344096" rpy="-1.943013564953089e-14 -8.597654057672277e-17 1.995298892452953e-15" />
            <geometry>
                <mesh filename="meshes/Tocha_Corpo.stl" scale="0.001 0.001 0.001" />
            </geometry>
        </collision>
    </link>
    <joint name="MESA-v1_Slider-1" type="prismatic">
        <origin xyz="0.0029999999999984783 0.027000000000001308 0.927" rpy="1.5707963267948952 -1.5707963267948966 0" />
        <parent link="MESA-v1" />
        <child link="CARRO-v1" />
        <axis xyz="0.0 -1.0 -1.7064081154941844e-16" />
        <limit lower="0.01" upper="1.68" effort="1000000" velocity="1000000" />
    </joint>
    <joint name="CARRO-v1_Slider-2" type="prismatic">
        <origin xyz="1.03748581 -1.5690375600000002 0.014999709999999737" rpy="-1.5707963267948966 -1.8947806286936004e-14 -3.233269041883932e-30" />
        <parent link="CARRO-v1" />
        <child link="CASTELO-v1" />
        <axis xyz="1.8947806286936004e-14 -1.0 5.053786356821182e-45" />
        <limit lower="-0.996" upper="-0.0245" effort="1000000" velocity="1000000" />
    </joint>
    <joint name="CASTELO-v1_Slider-3" type="prismatic">
        <origin xyz="-0.427000000000009 0.47075636999999193 0.08259919999999994" rpy="-1.5707963267948966 2.6604999814787466e-35 -1.5707963267948777" />
        <parent link="CASTELO-v1" />
        <child link="Z-v1" />
        <axis xyz="0.0 0.0 1.0" />
        <limit lower="-0.14" upper="0.25" effort="1000000" velocity="1000000" />
    </joint>
    <joint name="Tocha_Bocal_Rigid-4" type="fixed">
        <origin xyz="-0.8557192431605004 1.4890673583067839e-10 0.10000000433441131" rpy="1.943013564953089e-14 1.472088805341323e-16 -1.9952988924529516e-15" />
        <parent link="Tocha_Bocal" />
        <child link="Tocha_Corpo" />
    </joint>
    <joint name="Z-v1_Rigid-6" type="fixed">
        <origin xyz="0.0 0.0 -0.1789899299999999" rpy="-3.1415926535897825 -0.0 1.7995920690973877e-31" />
        <parent link="Z-v1" />
        <child link="Tocha_Corpo" />
    </joint>
</robot>